[2024-06-09T02:43:07.784+0000] {local_task_job_runner.py:120} INFO - ::group::Pre task execution logs
[2024-06-09T02:43:07.796+0000] {taskinstance.py:2076} INFO - Dependencies all met for dep_context=non-requeueable deps ti=<TaskInstance: FinSight_pipeline.visualize_data manual__2024-06-09T02:43:01.674113+00:00 [queued]>
[2024-06-09T02:43:07.800+0000] {taskinstance.py:2076} INFO - Dependencies all met for dep_context=requeueable deps ti=<TaskInstance: FinSight_pipeline.visualize_data manual__2024-06-09T02:43:01.674113+00:00 [queued]>
[2024-06-09T02:43:07.800+0000] {taskinstance.py:2306} INFO - Starting attempt 1 of 1
[2024-06-09T02:43:07.805+0000] {taskinstance.py:2330} INFO - Executing <Task(PythonOperator): visualize_data> on 2024-06-09 02:43:01.674113+00:00
[2024-06-09T02:43:07.810+0000] {warnings.py:110} WARNING - /home/***/.local/lib/python3.12/site-packages/***/task/task_runner/standard_task_runner.py:61: DeprecationWarning: This process (pid=177) is multi-threaded, use of fork() may lead to deadlocks in the child.
  pid = os.fork()

[2024-06-09T02:43:07.811+0000] {standard_task_runner.py:63} INFO - Started process 188 to run task
[2024-06-09T02:43:07.811+0000] {standard_task_runner.py:90} INFO - Running: ['***', 'tasks', 'run', 'FinSight_pipeline', 'visualize_data', 'manual__2024-06-09T02:43:01.674113+00:00', '--job-id', '42', '--raw', '--subdir', 'DAGS_FOLDER/FinSight/finsight_pipeline_taks.py', '--cfg-path', '/tmp/tmp8f393vs0']
[2024-06-09T02:43:07.813+0000] {standard_task_runner.py:91} INFO - Job 42: Subtask visualize_data
[2024-06-09T02:43:07.847+0000] {task_command.py:426} INFO - Running <TaskInstance: FinSight_pipeline.visualize_data manual__2024-06-09T02:43:01.674113+00:00 [running]> on host bc9e3c56deeb
[2024-06-09T02:43:07.931+0000] {taskinstance.py:2648} INFO - Exporting env vars: AIRFLOW_CTX_DAG_OWNER='Group 2' AIRFLOW_CTX_DAG_ID='FinSight_pipeline' AIRFLOW_CTX_TASK_ID='visualize_data' AIRFLOW_CTX_EXECUTION_DATE='2024-06-09T02:43:01.674113+00:00' AIRFLOW_CTX_TRY_NUMBER='1' AIRFLOW_CTX_DAG_RUN_ID='manual__2024-06-09T02:43:01.674113+00:00'
[2024-06-09T02:43:07.933+0000] {taskinstance.py:430} INFO - ::endgroup::
[2024-06-09T02:43:07.946+0000] {finsight_pipeline_functions.py:37} INFO - Reading data from                   Open        High  ...   Adj Close     Volume
Date                                ...                       
2002-05-23    1.156429    1.242857  ...    1.196429  104790000
2002-05-24    1.214286    1.225000  ...    1.210000   11104800
2002-05-28    1.213571    1.232143  ...    1.157143    6609400
2002-05-29    1.164286    1.164286  ...    1.103571    6757800
2002-05-30    1.107857    1.107857  ...    1.071429   10154200
...                ...         ...  ...         ...        ...
2022-12-23  296.179993  298.459991  ...  294.959991    4251100
2022-12-27  293.190002  293.570007  ...  284.170013    5778100
2022-12-28  281.920013  285.190002  ...  276.880005    5964400
2022-12-29  283.179993  295.500000  ...  291.119995    9588500
2022-12-30  285.529999  295.010010  ...  294.880005    7566900

[5189 rows x 6 columns]
[2024-06-09T02:43:07.946+0000] {finsight_pipeline_functions.py:43} INFO - Converting 'Date' column to datetime format and setting it as index.
[2024-06-09T02:43:07.947+0000] {finsight_pipeline_functions.py:94} ERROR - Failed to visualize or upload data: 'Date'
[2024-06-09T02:43:07.947+0000] {taskinstance.py:441} INFO - ::group::Post task execution logs
[2024-06-09T02:43:07.947+0000] {taskinstance.py:2905} ERROR - Task failed with exception
Traceback (most recent call last):
  File "/home/airflow/.local/lib/python3.12/site-packages/pandas/core/indexes/base.py", line 3791, in get_loc
    return self._engine.get_loc(casted_key)
           ^^^^^^^^^^^^^^^^^^^^^^^^^^^^^^^^
  File "index.pyx", line 152, in pandas._libs.index.IndexEngine.get_loc
  File "index.pyx", line 181, in pandas._libs.index.IndexEngine.get_loc
  File "pandas/_libs/hashtable_class_helper.pxi", line 7080, in pandas._libs.hashtable.PyObjectHashTable.get_item
  File "pandas/_libs/hashtable_class_helper.pxi", line 7088, in pandas._libs.hashtable.PyObjectHashTable.get_item
KeyError: 'Date'

The above exception was the direct cause of the following exception:

Traceback (most recent call last):
  File "/home/airflow/.local/lib/python3.12/site-packages/airflow/models/taskinstance.py", line 465, in _execute_task
    result = _execute_callable(context=context, **execute_callable_kwargs)
             ^^^^^^^^^^^^^^^^^^^^^^^^^^^^^^^^^^^^^^^^^^^^^^^^^^^^^^^^^^^^^
  File "/home/airflow/.local/lib/python3.12/site-packages/airflow/models/taskinstance.py", line 432, in _execute_callable
    return execute_callable(context=context, **execute_callable_kwargs)
           ^^^^^^^^^^^^^^^^^^^^^^^^^^^^^^^^^^^^^^^^^^^^^^^^^^^^^^^^^^^^
  File "/home/airflow/.local/lib/python3.12/site-packages/airflow/models/baseoperator.py", line 400, in wrapper
    return func(self, *args, **kwargs)
           ^^^^^^^^^^^^^^^^^^^^^^^^^^^
  File "/home/airflow/.local/lib/python3.12/site-packages/airflow/operators/python.py", line 235, in execute
    return_value = self.execute_callable()
                   ^^^^^^^^^^^^^^^^^^^^^^^
  File "/home/airflow/.local/lib/python3.12/site-packages/airflow/operators/python.py", line 252, in execute_callable
    return self.python_callable(*self.op_args, **self.op_kwargs)
           ^^^^^^^^^^^^^^^^^^^^^^^^^^^^^^^^^^^^^^^^^^^^^^^^^^^^^
  File "/opt/airflow/dags/FinSight/finsight_pipeline_functions.py", line 44, in visualize_raw_data
    df['Date'] = pd.to_datetime(df['Date'])
                                ~~^^^^^^^^
  File "/home/airflow/.local/lib/python3.12/site-packages/pandas/core/frame.py", line 3893, in __getitem__
    indexer = self.columns.get_loc(key)
              ^^^^^^^^^^^^^^^^^^^^^^^^^
  File "/home/airflow/.local/lib/python3.12/site-packages/pandas/core/indexes/base.py", line 3798, in get_loc
    raise KeyError(key) from err
KeyError: 'Date'
[2024-06-09T02:43:07.970+0000] {taskinstance.py:1206} INFO - Marking task as FAILED. dag_id=FinSight_pipeline, task_id=visualize_data, run_id=manual__2024-06-09T02:43:01.674113+00:00, execution_date=20240609T024301, start_date=20240609T024307, end_date=20240609T024307
[2024-06-09T02:43:07.983+0000] {standard_task_runner.py:110} ERROR - Failed to execute job 42 for task visualize_data ('Date'; 188)
[2024-06-09T02:43:07.992+0000] {local_task_job_runner.py:240} INFO - Task exited with return code 1
[2024-06-09T02:43:08.009+0000] {taskinstance.py:3498} INFO - 0 downstream tasks scheduled from follow-on schedule check
[2024-06-09T02:43:08.012+0000] {local_task_job_runner.py:222} INFO - ::endgroup::
